2020-09-29 19:17:56,083 INFO: Microblog startup [in /home/tkhara/notes/python/courses/miguel_grinberg/sandbox/7_section7_error_handling/microblog/app/__init__.py:43]
2020-09-29 19:32:33,203 INFO: Microblog startup [in /home/tkhara/notes/python/courses/miguel_grinberg/sandbox/7_section7_error_handling/microblog/app/__init__.py:43]
2020-09-29 19:32:50,596 ERROR: Exception on /edit_profile [POST] [in /home/tkhara/anaconda3/envs/microblog/lib/python3.8/site-packages/flask/app.py:1891]
Traceback (most recent call last):
  File "/home/tkhara/anaconda3/envs/microblog/lib/python3.8/site-packages/flask/app.py", line 2447, in wsgi_app
    response = self.full_dispatch_request()
  File "/home/tkhara/anaconda3/envs/microblog/lib/python3.8/site-packages/flask/app.py", line 1952, in full_dispatch_request
    rv = self.handle_user_exception(e)
  File "/home/tkhara/anaconda3/envs/microblog/lib/python3.8/site-packages/flask/app.py", line 1821, in handle_user_exception
    reraise(exc_type, exc_value, tb)
  File "/home/tkhara/anaconda3/envs/microblog/lib/python3.8/site-packages/flask/_compat.py", line 39, in reraise
    raise value
  File "/home/tkhara/anaconda3/envs/microblog/lib/python3.8/site-packages/flask/app.py", line 1950, in full_dispatch_request
    rv = self.dispatch_request()
  File "/home/tkhara/anaconda3/envs/microblog/lib/python3.8/site-packages/flask/app.py", line 1936, in dispatch_request
    return self.view_functions[rule.endpoint](**req.view_args)
  File "/home/tkhara/anaconda3/envs/microblog/lib/python3.8/site-packages/flask_login/utils.py", line 272, in decorated_view
    return func(*args, **kwargs)
  File "/home/tkhara/notes/python/courses/miguel_grinberg/sandbox/7_section7_error_handling/microblog/app/routes.py", line 94, in edit_profile
    if form.validate_on_submit():
  File "/home/tkhara/anaconda3/envs/microblog/lib/python3.8/site-packages/flask_wtf/form.py", line 100, in validate_on_submit
    return self.is_submitted() and self.validate()
  File "/home/tkhara/anaconda3/envs/microblog/lib/python3.8/site-packages/wtforms/form.py", line 318, in validate
    return super(Form, self).validate(extra)
  File "/home/tkhara/anaconda3/envs/microblog/lib/python3.8/site-packages/wtforms/form.py", line 150, in validate
    if not field.validate(self, extra):
  File "/home/tkhara/anaconda3/envs/microblog/lib/python3.8/site-packages/wtforms/fields/core.py", line 226, in validate
    stop_validation = self._run_validation_chain(form, chain)
  File "/home/tkhara/anaconda3/envs/microblog/lib/python3.8/site-packages/wtforms/fields/core.py", line 246, in _run_validation_chain
    validator(form, self)
  File "/home/tkhara/notes/python/courses/miguel_grinberg/sandbox/7_section7_error_handling/microblog/app/forms.py", line 40, in validate_username
    user = User.query.filter_by(email=email.data).first()
NameError: name 'email' is not defined
2020-09-29 19:35:50,842 INFO: Microblog startup [in /home/tkhara/notes/python/courses/miguel_grinberg/sandbox/7_section7_error_handling/microblog/app/__init__.py:43]
2020-09-29 19:36:35,029 INFO: Microblog startup [in /home/tkhara/notes/python/courses/miguel_grinberg/sandbox/7_section7_error_handling/microblog/app/__init__.py:43]
